Workbook

Sheet transitions
A1: building | B1: category | C1: month_index | D1: year | E1: month | F1: period | G1: from_state | H1: to_state | I1: transition_label | J1: works_added | K1: start_month | L1: end_month | M1: end_month_index | N1: start_year | O1: end_year | P1: end_month_in_year | Q1: duration_months | R1: cost | S1: gain | T1: is_instant
A2: abri_bouliste | B2: Sports | C2: 218 | D2: 2044 | E2: 3 | F2: 2044-03 | G2: none | H2: abri_bouliste_simulation_11 | I2: none -> abri_bouliste_simulation_11 | J2: indoor_wall_isolation, window_replacement_DG, floor_isolation, roof_isolation | K2: 218 | L2: 219 | M2: 218 | N2: 2044 | O2: 2044 | P2: 3 | Q2: 1 | R2: 62094.12 | S2: 6.087383 | T2: FALSE
A3: accueil_de_loisirs_maternel_la_varenne | B3: Enseignement | C3: 203 | D3: 2042 | E3: 12 | F3: 2042-12 | G3: none | H3: accueil_de_loisirs_maternel_la_varenne_simulation_14 | I3: none -> accueil_de_loisirs_maternel_la_varenne_simulation_14 | J3: indoor_wall_isolation, window_replacement_TG, floor_isolation, roof_isolation | K3: 203 | L3: 205 | M3: 204 | N3: 2042 | O3: 2043 | P3: 1 | Q3: 2 | R3: 241467.91 | S3: 3.3197771 | T3: FALSE
A4: association_31_rue_gambetta | B4: Autres | C4: 85 | D4: 2033 | E4: 2 | F4: 2033-02 | G4: none | H4: association_31_rue_gambetta_simulation_6 | I4: none -> association_31_rue_gambetta_simulation_6 | J4: indoor_wall_isolation, window_replacement_DG, roof_isolation | K4: 85 | L4: 87 | M4: 86 | N4: 2033 | O4: 2033 | P4: 3 | Q4: 2 | R4: 167051.5 | S4: 7.325672 | T4: FALSE
A5: ateliers_municipaux_(ctm) | B5: Administration | C5: 175 | D5: 2040 | E5: 8 | F5: 2040-08 | G5: none | H5: ateliers_municipaux_(ctm)_simulation_7 | I5: none -> ateliers_municipaux_(ctm)_simulation_7 | J5: exterior_wall_isolation, window_replacement_DG, roof_isolation, VMC_installation | K5: 175 | L5: 184 | M5: 183 | N5: 2040 | O5: 2041 | P5: 4 | Q5: 9 | R5: 1981177.1 | S5: 639.42421 | T5: FALSE
A6: ateliers_municipaux_(ctm) | B6: Administration | C6: 184 | D6: 2041 | E6: 5 | F6: 2041-05 | G6: ateliers_municipaux_(ctm)_simulation_7 | H6: ateliers_municipaux_(ctm)_simulation_9 | I6: ateliers_municipaux_(ctm)_simulation_7 -> ateliers_municipaux_(ctm)_simulation_9 | J6: system_installation | K6: 184 | L6: 193 | M6: 192 | N6: 2041 | O6: 2042 | P6: 1 | Q6: 9 | R6: 14380.36 | S6: 36.46005 | T6: FALSE
A7: base_de_canoe_kayak | B7: Sports | C7: 266 | D7: 2048 | E7: 3 | F7: 2048-03 | G7: none | H7: base_de_canoe_kayak_simulation_12 | I7: none -> base_de_canoe_kayak_simulation_12 | J7: indoor_wall_isolation, floor_isolation, roof_isolation | K7: 266 | L7: 267 | M7: 266 | N7: 2048 | O7: 2048 | P7: 3 | Q7: 1 | R7: 28031.7 | S7: 13.615677 | T7: FALSE
A8: bureaux_21_rue_des_sports | B8: Autres | C8: 80 | D8: 2032 | E8: 9 | F8: 2032-09 | G8: none | H8: bureaux_21_rue_des_sports_simulation_14 | I8: none -> bureaux_21_rue_des_sports_simulation_14 | J8: indoor_wall_isolation, window_replacement_DG, roof_isolation | K8: 80 | L8: 81 | M8: 80 | N8: 2032 | O8: 2032 | P8: 9 | Q8: 1 | R8: 43496.537 | S8: 2.8604503 | T8: FALSE
A9: cdj_du_champy | B9: Autres | C9: 284 | D9: 2049 | E9: 9 | F9: 2049-09 | G9: none | H9: cdj_du_champy_simulation_8 | I9: none -> cdj_du_champy_simulation_8 | J9: indoor_wall_isolation, floor_isolation, roof_isolation, VMC_installation | K9: 284 | L9: 286 | M9: 285 | N9: 2049 | O9: 2049 | P9: 10 | Q9: 2 | R9: 166570.65 | S9: 20.554261 | T9: FALSE
A10: cdj_du_pave_neuf | B10: Autres | C10: 94 | D10: 2033 | E10: 11 | F10: 2033-11 | G10: none | H10: cdj_du_pave_neuf_simulation_1 | I10: none -> cdj_du_pave_neuf_simulation_1 | J10: indoor_wall_isolation | K10: 94 | L10: 96 | M10: 95 | N10: 2033 | O10: 2033 | P10: 12 | Q10: 2 | R10: 26123.489 | S10: 9.0161419 | T10: FALSE
A11: cdj_du_pave_neuf | B11: Autres | C11: 96 | D11: 2034 | E11: 1 | F11: 2034-01 | G11: cdj_du_pave_neuf_simulation_1 | H11: cdj_du_pave_neuf_simulation_11 | I11: cdj_du_pave_neuf_simulation_1 -> cdj_du_pave_neuf_simulation_11 | J11: floor_isolation, roof_isolation, VMC_installation | K11: 96 | L11: 98 | M11: 97 | N11: 2034 | O11: 2034 | P11: 2 | Q11: 2 | R11: 129716.67 | S11: 8.1771689 | T11: FALSE
A12: centre_aquatique_les_nymphéas | B12: Sports | C12: 125 | D12: 2036 | E12: 6 | F12: 2036-06 | G12: none | H12: centre_aquatique_les_nymphéas_simulation_1 | I12: none -> centre_aquatique_les_nymphéas_simulation_1 | J12: floor_isolation | K12: 125 | L12: 134 | M12: 133 | N12: 2036 | O12: 2037 | P12: 2 | Q12: 9 | R12: 358316.06 | S12: 63.596638 | T12: FALSE
A13: centre_horticole | B13: Administration | C13: 254 | D13: 2047 | E13: 3 | F13: 2047-03 | G13: none | H13: centre_horticole_simulation_15 | I13: none -> centre_horticole_simulation_15 | J13: exterior_wall_isolation, window_replacement_TG, roof_isolation | K13: 254 | L13: 256 | M13: 255 | N13: 2047 | O13: 2047 | P13: 4 | Q13: 2 | R13: 183773.7 | S13: 7.2991202 | T13: FALSE
... A110: villa_cathala | B110: Autres | C110: 170 | D110: 2040 | E110: 3 | F110: 2040-03 | G110: villa_cathala_simulation 2 | H110: villa_cathala_simulation 10 | I110: villa_cathala_simulation 2 -> villa_cathala_simulation 10 | J110: window_replacement_TG, VMC_installation | K110: 170 | L110: 172 | M110: 171 | N110: 2040 | O110: 2040 | P110: 4 | Q110: 2 | R110: 237403.9 | S110: 13.16982 | T110: FALSE

Sheet timeline_renovations
A1: building | B1: 2026-01 | C1: 2026-02 | D1: 2026-03 | E1: 2026-04 | F1: 2026-05 | G1: 2026-06 | H1: 2026-07 | I1: 2026-08 | J1: 2026-09 | K1: 2026-10 | L1: 2026-11 | M1: 2026-12 | N1: 2027-01 | O1: 2027-02 | P1: 2027-03 | Q1: 2027-04 | R1: 2027-05 | S1: 2027-06 | T1: 2027-07 | U1: 2027-08 | V1: 2027-09 | W1: 2027-10 | X1: 2027-11 | Y1: 2027-12 | Z1: 2028-01 | AA1: 2028-02 | AB1: 2028-03 | AC1: 2028-04 | AD1: 2028-05 | AE1: 2028-06 | AF1: 2028-07 | AG1: 2028-08 | AH1: 2028-09 | AI1: 2028-10 | AJ1: 2028-11 | AK1: 2028-12 | AL1: 2029-01 | AM1: 2029-02 | AN1: 2029-03 | AO1: 2029-04 | AP1: 2029-05 | AQ1: 2029-06 | AR1: 2029-07 | AS1: 2029-08 | AT1: 2029-09 | AU1: 2029-10 | AV1: 2029-11 | AW1: 2029-12 | AX1: 2030-01 | AY1: 2030-02 | AZ1: 2030-03 | BA1: 2030-04 | BB1: 2030-05 | BC1: 2030-06 | BD1: 2030-07 | BE1: 2030-08 | BF1: 2030-09 | BG1: 2030-10 | BH1: 2030-11 | BI1: 2030-12 | BJ1: 2031-01 | BK1: 2031-02 | BL1: 2031-03 | BM1: 2031-04 | BN1: 2031-05 | BO1: 2031-06 | BP1: 2031-07 | BQ1: 2031-08 | BR1: 2031-09 | BS1: 2031-10 | BT1: 2031-11 | BU1: 2031-12 | BV1: 2032-01 | BW1: 2032-02 | BX1: 2032-03 | BY1: 2032-04 | BZ1: 2032-05 | CA1: 2032-06 | CB1: 2032-07 | CC1: 2032-08 | CD1: 2032-09 | CE1: 2032-10 | CF1: 2032-11 | CG1: 2032-12 | CH1: 2033-01 | CI1: 2033-02 | CJ1: 2033-03 | CK1: 2033-04 | CL1: 2033-05 | CM1: 2033-06 | CN1: 2033-07 | CO1: 2033-08 | CP1: 2033-09 | CQ1: 2033-10 | CR1: 2033-11 | CS1: 2033-12 | CT1: 2034-01 | CU1: 2034-02 | CV1: 2034-03 | CW1: 2034-04 | CX1: 2034-05 | CY1: 2034-06 | CZ1: 2034-07 | DA1: 2034-08 | DB1: 2034-09 | DC1: 2034-10 | DD1: 2034-11 | DE1: 2034-12 | DF1: 2035-01 | DG1: 2035-02 | DH1: 2035-03 | DI1: 2035-04 | DJ1: 2035-05 | DK1: 2035-06 | DL1: 2035-07 | DM1: 2035-08 | DN1: 2035-09 | DO1: 2035-10 | DP1: 2035-11 | DQ1: 2035-12 | DR1: 2036-01 | DS1: 2036-02 | DT1: 2036-03 | DU1: 2036-04 | DV1: 2036-05 | DW1: 2036-06 | DX1: 2036-07 | DY1: 2036-08 | DZ1: 2036-09 | EA1: 2036-10 | EB1: 2036-11 | EC1: 2036-12 | ED1: 2037-01 | EE1: 2037-02 | EF1: 2037-03 | EG1: 2037-04 | EH1: 2037-05 | EI1: 2037-06 | EJ1: 2037-07 | EK1: 2037-08 | EL1: 2037-09 | EM1: 2037-10 | EN1: 2037-11 | EO1: 2037-12 | EP1: 2038-01 | EQ1: 2038-02 | ER1: 2038-03 | ES1: 2038-04 | ET1: 2038-05 | EU1: 2038-06 | EV1: 2038-07 | EW1: 2038-08 | EX1: 2038-09 | EY1: 2038-10 | EZ1: 2038-11 | FA1: 2038-12 | FB1: 2039-01 | FC1: 2039-02 | FD1: 2039-03 | FE1: 2039-04 | FF1: 2039-05 | FG1: 2039-06 | FH1: 2039-07 | FI1: 2039-08 | FJ1: 2039-09 | FK1: 2039-10 | FL1: 2039-11 | FM1: 2039-12 | FN1: 2040-01 | FO1: 2040-02 | FP1: 2040-03 | FQ1: 2040-04 | FR1: 2040-05 | FS1: 2040-06 | FT1: 2040-07 | FU1: 2040-08 | FV1: 2040-09 | FW1: 2040-10 | FX1: 2040-11 | FY1: 2040-12 | FZ1: 2041-01 | GA1: 2041-02 | GB1: 2041-03 | GC1: 2041-04 | GD1: 2041-05 | GE1: 2041-06 | GF1: 2041-07 | GG1: 2041-08 | GH1: 2041-09 | GI1: 2041-10 | GJ1: 2041-11 | GK1: 2041-12 | GL1: 2042-01 | GM1: 2042-02 | GN1: 2042-03 | GO1: 2042-04 | GP1: 2042-05 | GQ1: 2042-06 | GR1: 2042-07 | GS1: 2042-08 | GT1: 2042-09 | GU1: 2042-10 | GV1: 2042-11 | GW1: 2042-12 | GX1: 2043-01 | GY1: 2043-02 | GZ1: 2043-03 | HA1: 2043-04 | HB1: 2043-05 | HC1: 2043-06 | HD1: 2043-07 | HE1: 2043-08 | HF1: 2043-09 | HG1: 2043-10 | HH1: 2043-11 | HI1: 2043-12 | HJ1: 2044-01 | HK1: 2044-02 | HL1: 2044-03 | HM1: 2044-04 | HN1: 2044-05 | HO1: 2044-06 | HP1: 2044-07 | HQ1: 2044-08 | HR1: 2044-09 | HS1: 2044-10 | HT1: 2044-11 | HU1: 2044-12 | HV1: 2045-01 | HW1: 2045-02 | HX1: 2045-03 | HY1: 2045-04 | HZ1: 2045-05 | IA1: 2045-06 | IB1: 2045-07 | IC1: 2045-08 | ID1: 2045-09 | IE1: 2045-10 | IF1: 2045-11 | IG1: 2045-12 | IH1: 2046-01 | II1: 2046-02 | IJ1: 2046-03 | IK1: 2046-04 | IL1: 2046-05 | IM1: 2046-06 | IN1: 2046-07 | IO1: 2046-08 | IP1: 2046-09 | IQ1: 2046-10 | IR1: 2046-11 | IS1: 2046-12 | IT1: 2047-01 | IU1: 2047-02 | IV1: 2047-03 | IW1: 2047-04 | IX1: 2047-05 | IY1: 2047-06 | IZ1: 2047-07 | JA1: 2047-08 | JB1: 2047-09 | JC1: 2047-10 | JD1: 2047-11 | JE1: 2047-12 | JF1: 2048-01 | JG1: 2048-02 | JH1: 2048-03 | JI1: 2048-04 | JJ1: 2048-05 | JK1: 2048-06 | JL1: 2048-07 | JM1: 2048-08 | JN1: 2048-09 | JO1: 2048-10 | JP1: 2048-11 | JQ1: 2048-12 | JR1: 2049-01 | JS1: 2049-02 | JT1: 2049-03 | JU1: 2049-04 | JV1: 2049-05 | JW1: 2049-06 | JX1: 2049-07 | JY1: 2049-08 | JZ1: 2049-09 | KA1: 2049-10 | KB1: 2049-11 | KC1: 2049-12 | KD1: 2050-01 | KE1: 2050-02 | KF1: 2050-03 | KG1: 2050-04 | KH1: 2050-05 | KI1: 2050-06 | KJ1: 2050-07 | KK1: 2050-08 | KL1: 2050-09 | KM1: 2050-10 | KN1: 2050-11 | KO1: 2050-12
A2: abri_bouliste | HL2: none -> abri_bouliste_simulation_11
A3: accueil_de_loisirs_maternel_la_varenne | GW3: none -> accueil_de_loisirs_maternel_la_varenne_simulation_14
A4: association_31_rue_gambetta | CI4: none -> association_31_rue_gambetta_simulation_6
A5: ateliers_municipaux_(ctm) | FU5: none -> ateliers_municipaux_(ctm)_simulation_7 | GD5: ateliers_municipaux_(ctm)_simulation_7 -> ateliers_municipaux_(ctm)_simulation_9
A6: base_de_canoe_kayak | JH6: none -> base_de_canoe_kayak_simulation_12
A7: bureaux_21_rue_des_sports | CD7: none -> bureaux_21_rue_des_sports_simulation_14
A8: cdj_du_champy | JZ8: none -> cdj_du_champy_simulation_8
A9: cdj_du_pave_neuf | CR9: none -> cdj_du_pave_neuf_simulation_1 | CT9: cdj_du_pave_neuf_simulation_1 -> cdj_du_pave_neuf_simulation_11
A10: centre_aquatique_les_nymphéas | DW10: none -> centre_aquatique_les_nymphéas_simulation_1
A11: centre_horticole | IV11: none -> centre_horticole_simulation_15
A12: cimetiere_nouveau | EO12: none -> cimetiere_nouveau_simulation_9 | EP12: cimetiere_nouveau_simulation_9 -> cimetiere_nouveau_simulation_11
A13: cinéma_le_bijou | B13: none -> cinéma_le_bijou_simulation_7
A14: club_ricardo_bofil | KL14: none -> club_ricardo_bofil_simulation_2
A15: conservatoire_maurice_bacquet | ID15: none -> conservatoire_maurice_bacquet_simulation 1 | IF15: conservatoire_maurice_bacquet_simulation 1 -> conservatoire_maurice_bacquet_simulation 10
A16: creche_multi_accueil_des_farfadets | JG16: none -> creche_multi_accueil_des_farfadets_simulation_2
A17: crèche_et_halte_du_marnois | HP17: none -> crèche_et_halte_du_marnois_simulation_5
A18: crèche_familiale_du_champy_-_relais_des_assistances_maternelles | GS18: none -> crèche_familiale_du_champy_-_relais_des_assistances_maternelles_simulation_4
A19: crèche_petit_prince | N19: none -> crèche_petit_prince_simulation_1 | EX19: crèche_petit_prince_simulation_1 -> crèche_petit_prince_simulation_4
A20: crèche_robert_debré | AU20: none -> crèche_robert_debré_simulation_6 | BX20: crèche_robert_debré_simulation_6 -> crèche_robert_debré_simulation_10
A21: déchèterie_municipale | BI21: none -> déchèterie_municipale_simulation_11
A22: emaus_1_et__2 | EJ22: none -> emaus_1_et__2_simulation_15
A23: espace_michel_simon | AW23: none -> espace_michel_simon_simulation 4 | BI23: espace_michel_simon_simulation 4 -> espace_michel_simon_simulation 10
A24: groupe_scolaire_des_hauts_bâtons | GA24: none -> groupe_scolaire_des_hauts_bâtons_simulation_5 | JT24: groupe_scolaire_des_hauts_bâtons_simulation_5 -> groupe_scolaire_des_hauts_bâtons_simulation_7
A25: groupe_scolaire_les_coteaux | HS25: none -> groupe_scolaire_les_coteaux_simulation_10
A26: groupe_scolaire_les_richardets | T26: none -> groupe_scolaire_les_richardets_simulation_1
A27: groupe_scolaire_paul_serelle | KI27: none -> groupe_scolaire_paul_serelle_simulation_1
A28: groupe_scolaire_robert_desnos | EK28: none -> groupe_scolaire_robert_desnos_simulation_8 | ES28: groupe_scolaire_robert_desnos_simulation_8 -> groupe_scolaire_robert_desnos_simulation_10
A29: gs_alex_dumas | AJ29: none -> gs_alex_dumas_simulation 10
A30: gs_celestin_freinet | CA30: none -> gs_celestin_freinet_simulation 10
A31: gs_clos_arche | IL31: none -> gs_clos_arche_simulation 6 | IS31: gs_clos_arche_simulation 6 -> gs_clos_arche_simulation 10
A32: gs_clos_dambert | B32: none -> gs_clos_dambert_simulation 3 | EY32: gs_clos_dambert_simulation 3 -> gs_clos_dambert_simulation 7
A33: gs_george_brassens | IB33: none -> gs_george_brassens_simulation 8
A34: gs_joliot_curie | CG34: none -> gs_joliot_curie_simulation 3 | GP34: gs_joliot_curie_simulation 3 -> gs_joliot_curie_simulation 9
A35: gs_jules_ferry | DL35: none -> gs_jules_ferry_simulation 3 | EY35: gs_jules_ferry_simulation 3 -> gs_jules_ferry_simulation 10
A36: gs_jules_verne | CL36: none -> gs_jules_verne_simulation 10
A37: gs_la_varenne | FK37: none -> gs_la_varenne_simulation 3 | GG37: gs_la_varenne_simulation 3 -> gs_la_varenne_simulation 10
A38: gs_les_abeilles | JP38: none -> gs_les_abeilles_simulation 7 | JQ38: gs_les_abeilles_simulation 7 -> gs_les_abeilles_simulation 10
A39: gs_les_charmilles | EA39: none -> gs_les_charmilles_simulation 10
A40: gs_les_noyers | DO40: none -> gs_les_noyers_simulation 10
...

Sheet timeline_travaux
A1: building | B1: 2026-01 | C1: 2026-02 | D1: 2026-03 | E1: 2026-04 | F1: 2026-05 | G1: 2026-06 | H1: 2026-07 | I1: 2026-08 | J1: 2026-09 | K1: 2026-10 | L1: 2026-11 | M1: 2026-12 | N1: 2027-01 | O1: 2027-02 | P1: 2027-03 | Q1: 2027-04 | R1: 2027-05 | S1: 2027-06 | T1: 2027-07 | U1: 2027-08 | V1: 2027-09 | W1: 2027-10 | X1: 2027-11 | Y1: 2027-12 | Z1: 2028-01 | AA1: 2028-02 | AB1: 2028-03 | AC1: 2028-04 | AD1: 2028-05 | AE1: 2028-06 | AF1: 2028-07 | AG1: 2028-08 | AH1: 2028-09 | AI1: 2028-10 | AJ1: 2028-11 | AK1: 2028-12 | AL1: 2029-01 | AM1: 2029-02 | AN1: 2029-03 | AO1: 2029-04 | AP1: 2029-05 | AQ1: 2029-06 | AR1: 2029-07 | AS1: 2029-08 | AT1: 2029-09 | AU1: 2029-10 | AV1: 2029-11 | AW1: 2029-12 | AX1: 2030-01 | AY1: 2030-02 | AZ1: 2030-03 | BA1: 2030-04 | BB1: 2030-05 | BC1: 2030-06 | BD1: 2030-07 | BE1: 2030-08 | BF1: 2030-09 | BG1: 2030-10 | BH1: 2030-11 | BI1: 2030-12 | BJ1: 2031-01 | BK1: 2031-02 | BL1: 2031-03 | BM1: 2031-04 | BN1: 2031-05 | BO1: 2031-06 | BP1: 2031-07 | BQ1: 2031-08 | BR1: 2031-09 | BS1: 2031-10 | BT1: 2031-11 | BU1: 2031-12 | BV1: 2032-01 | BW1: 2032-02 | BX1: 2032-03 | BY1: 2032-04 | BZ1: 2032-05 | CA1: 2032-06 | CB1: 2032-07 | CC1: 2032-08 | CD1: 2032-09 | CE1: 2032-10 | CF1: 2032-11 | CG1: 2032-12 | CH1: 2033-01 | CI1: 2033-02 | CJ1: 2033-03 | CK1: 2033-04 | CL1: 2033-05 | CM1: 2033-06 | CN1: 2033-07 | CO1: 2033-08 | CP1: 2033-09 | CQ1: 2033-10 | CR1: 2033-11 | CS1: 2033-12 | CT1: 2034-01 | CU1: 2034-02 | CV1: 2034-03 | CW1: 2034-04 | CX1: 2034-05 | CY1: 2034-06 | CZ1: 2034-07 | DA1: 2034-08 | DB1: 2034-09 | DC1: 2034-10 | DD1: 2034-11 | DE1: 2034-12 | DF1: 2035-01 | DG1: 2035-02 | DH1: 2035-03 | DI1: 2035-04 | DJ1: 2035-05 | DK1: 2035-06 | DL1: 2035-07 | DM1: 2035-08 | DN1: 2035-09 | DO1: 2035-10 | DP1: 2035-11 | DQ1: 2035-12 | DR1: 2036-01 | DS1: 2036-02 | DT1: 2036-03 | DU1: 2036-04 | DV1: 2036-05 | DW1: 2036-06 | DX1: 2036-07 | DY1: 2036-08 | DZ1: 2036-09 | EA1: 2036-10 | EB1: 2036-11 | EC1: 2036-12 | ED1: 2037-01 | EE1: 2037-02 | EF1: 2037-03 | EG1: 2037-04 | EH1: 2037-05 | EI1: 2037-06 | EJ1: 2037-07 | EK1: 2037-08 | EL1: 2037-09 | EM1: 2037-10 | EN1: 2037-11 | EO1: 2037-12 | EP1: 2038-01 | EQ1: 2038-02 | ER1: 2038-03 | ES1: 2038-04 | ET1: 2038-05 | EU1: 2038-06 | EV1: 2038-07 | EW1: 2038-08 | EX1: 2038-09 | EY1: 2038-10 | EZ1: 2038-11 | FA1: 2038-12 | FB1: 2039-01 | FC1: 2039-02 | FD1: 2039-03 | FE1: 2039-04 | FF1: 2039-05 | FG1: 2039-06 | FH1: 2039-07 | FI1: 2039-08 | FJ1: 2039-09 | FK1: 2039-10 | FL1: 2039-11 | FM1: 2039-12 | FN1: 2040-01 | FO1: 2040-02 | FP1: 2040-03 | FQ1: 2040-04 | FR1: 2040-05 | FS1: 2040-06 | FT1: 2040-07 | FU1: 2040-08 | FV1: 2040-09 | FW1: 2040-10 | FX1: 2040-11 | FY1: 2040-12 | FZ1: 2041-01 | GA1: 2041-02 | GB1: 2041-03 | GC1: 2041-04 | GD1: 2041-05 | GE1: 2041-06 | GF1: 2041-07 | GG1: 2041-08 | GH1: 2041-09 | GI1: 2041-10 | GJ1: 2041-11 | GK1: 2041-12 | GL1: 2042-01 | GM1: 2042-02 | GN1: 2042-03 | GO1: 2042-04 | GP1: 2042-05 | GQ1: 2042-06 | GR1: 2042-07 | GS1: 2042-08 | GT1: 2042-09 | GU1: 2042-10 | GV1: 2042-11 | GW1: 2042-12 | GX1: 2043-01 | GY1: 2043-02 | GZ1: 2043-03 | HA1: 2043-04 | HB1: 2043-05 | HC1: 2043-06 | HD1: 2043-07 | HE1: 2043-08 | HF1: 2043-09 | HG1: 2043-10 | HH1: 2043-11 | HI1: 2043-12 | HJ1: 2044-01 | HK1: 2044-02 | HL1: 2044-03 | HM1: 2044-04 | HN1: 2044-05 | HO1: 2044-06 | HP1: 2044-07 | HQ1: 2044-08 | HR1: 2044-09 | HS1: 2044-10 | HT1: 2044-11 | HU1: 2044-12 | HV1: 2045-01 | HW1: 2045-02 | HX1: 2045-03 | HY1: 2045-04 | HZ1: 2045-05 | IA1: 2045-06 | IB1: 2045-07 | IC1: 2045-08 | ID1: 2045-09 | IE1: 2045-10 | IF1: 2045-11 | IG1: 2045-12 | IH1: 2046-01 | II1: 2046-02 | IJ1: 2046-03 | IK1: 2046-04 | IL1: 2046-05 | IM1: 2046-06 | IN1: 2046-07 | IO1: 2046-08 | IP1: 2046-09 | IQ1: 2046-10 | IR1: 2046-11 | IS1: 2046-12 | IT1: 2047-01 | IU1: 2047-02 | IV1: 2047-03 | IW1: 2047-04 | IX1: 2047-05 | IY1: 2047-06 | IZ1: 2047-07 | JA1: 2047-08 | JB1: 2047-09 | JC1: 2047-10 | JD1: 2047-11 | JE1: 2047-12 | JF1: 2048-01 | JG1: 2048-02 | JH1: 2048-03 | JI1: 2048-04 | JJ1: 2048-05 | JK1: 2048-06 | JL1: 2048-07 | JM1: 2048-08 | JN1: 2048-09 | JO1: 2048-10 | JP1: 2048-11 | JQ1: 2048-12 | JR1: 2049-01 | JS1: 2049-02 | JT1: 2049-03 | JU1: 2049-04 | JV1: 2049-05 | JW1: 2049-06 | JX1: 2049-07 | JY1: 2049-08 | JZ1: 2049-09 | KA1: 2049-10 | KB1: 2049-11 | KC1: 2049-12 | KD1: 2050-01 | KE1: 2050-02 | KF1: 2050-03 | KG1: 2050-04 | KH1: 2050-05 | KI1: 2050-06 | KJ1: 2050-07 | KK1: 2050-08 | KL1: 2050-09 | KM1: 2050-10 | KN1: 2050-11 | KO1: 2050-12
A2: abri_bouliste | HL2: indoor_wall_isolation, window_replacement_DG, floor_isolation, roof_isolation
A3: accueil_de_loisirs_maternel_la_varenne | GW3: indoor_wall_isolation, window_replacement_TG, floor_isolation, roof_isolation
A4: association_31_rue_gambetta | CI4: indoor_wall_isolation, window_replacement_DG, roof_isolation
A5: ateliers_municipaux_(ctm) | FU5: exterior_wall_isolation, window_replacement_DG, roof_isolation, VMC_installation | GD5: system_installation
A6: base_de_canoe_kayak | JH6: indoor_wall_isolation, floor_isolation, roof_isolation
A7: bureaux_21_rue_des_sports | CD7: indoor_wall_isolation, window_replacement_DG, roof_isolation
A8: cdj_du_champy | JZ8: indoor_wall_isolation, floor_isolation, roof_isolation, VMC_installation
A9: cdj_du_pave_neuf | CR9: indoor_wall_isolation | CT9: floor_isolation, roof_isolation, VMC_installation
A10: centre_aquatique_les_nymphéas | DW10: floor_isolation
A11: centre_horticole | IV11: exterior_wall_isolation, window_replacement_TG, roof_isolation
A12: cimetiere_nouveau | EO12: floor_isolation | EP12: indoor_wall_isolation, roof_isolation, VMC_installation
A13: cinéma_le_bijou | B13: window_replacement_TG, floor_isolation, system_installation
A14: club_ricardo_bofil | KL14: indoor_wall_isolation, floor_isolation
A15: conservatoire_maurice_bacquet | ID15: floor_isolation | IF15: indoor_wall_isolation, VMC_installation, system_installation
A16: creche_multi_accueil_des_farfadets | JG16: indoor_wall_isolation, floor_isolation
A17: crèche_et_halte_du_marnois | HP17: VMC_installation | indoor_wall_isolation, window_replacement_DG, roof_isolation
A18: crèche_familiale_du_champy_-_relais_des_assistances_maternelles | GS18: VMC_installation | exterior_wall_isolation, window_replacement_DG, floor_isolation
A19: crèche_petit_prince | N19: exterior_wall_isolation | EX19: window_replacement_TG
A20: crèche_robert_debré | AU20: window_replacement_DG, roof_isolation, VMC_installation | BX20: indoor_wall_isolation, system_installation
A21: déchèterie_municipale | BI21: indoor_wall_isolation, floor_isolation, roof_isolation, VMC_installation
A22: emaus_1_et__2 | EJ22: indoor_wall_isolation, window_replacement_DG, floor_isolation, roof_isolation
A23: espace_michel_simon | AW23: window_replacement_DG | BI23: indoor_wall_isolation, floor_isolation, roof_isolation, VMC_installation, system_installation
A24: groupe_scolaire_des_hauts_bâtons | GA24: system_installation | JT24: exterior_wall_isolation, roof_isolation
A25: groupe_scolaire_les_coteaux | HS25: exterior_wall_isolation, window_replacement_DG, VMC_installation
A26: groupe_scolaire_les_richardets | T26: exterior_wall_isolation, floor_isolation, roof_isolation, VMC_installation, system_installation
A27: groupe_scolaire_paul_serelle | KI27: exterior_wall_isolation, floor_isolation, roof_isolation
A28: groupe_scolaire_robert_desnos | EK28: indoor_wall_isolation, window_replacement_DG, roof_isolation | ES28: VMC_installation, system_installation
A29: gs_alex_dumas | AJ29: exterior_wall_isolation, window_replacement_TG, VMC_installation, system_installation
A30: gs_celestin_freinet | CA30: indoor_wall_isolation, window_replacement_DG, roof_isolation, VMC_installation
A31: gs_clos_arche | IL31: indoor_wall_isolation, window_replacement_DG | IS31: floor_isolation, VMC_installation, system_installation
A32: gs_clos_dambert | B32: window_replacement_DG | EY32: VMC_installation
A33: gs_george_brassens | IB33: exterior_wall_isolation, window_replacement_TG, floor_isolation, roof_isolation
A34: gs_joliot_curie | CG34: system_installation | GP34: exterior_wall_isolation, roof_isolation, VMC_installation
A35: gs_jules_ferry | DL35: window_replacement_TG | EY35: exterior_wall_isolation, floor_isolation, VMC_installation, system_installation
A36: gs_jules_verne | CL36: exterior_wall_isolation, window_replacement_DG, floor_isolation, VMC_installation
A37: gs_la_varenne | FK37: window_replacement_TG | GG37: exterior_wall_isolation, floor_isolation, system_installation
A38: gs_les_abeilles | JP38: system_installation | JQ38: exterior_wall_isolation, window_replacement_DG, roof_isolation, VMC_installation
A39: gs_les_charmilles | EA39: indoor_wall_isolation, window_replacement_DG, VMC_installation
A40: gs_les_noyers | DO40: indoor_wall_isolation, window_replacement_DG, roof_isolation, system_installation
...

Sheet stats_mois
A1: year | B1: month | C1: period | D1: renovations_started | E1: cost_total_started | F1: renovations_instant
A2: 2026 | B2: 1 | C2: 2026-01 | D2: 3 | E2: 1256157.8 | F2: 0
A3: 2026 | B3: 2 | C3: 2026-02 | D3: 0 | E3: 0 | F3: 0
A4: 2026 | B4: 3 | C4: 2026-03 | D4: 0 | E4: 0 | F4: 0
A5: 2026 | B5: 4 | C5: 2026-04 | D5: 0 | E5: 0 | F5: 0
A6: 2026 | B6: 5 | C6: 2026-05 | D6: 0 | E6: 0 | F6: 0
A7: 2026 | B7: 6 | C7: 2026-06 | D7: 0 | E7: 0 | F7: 0
A8: 2026 | B8: 7 | C8: 2026-07 | D8: 2 | E8: 1691225.8 | F8: 1
A9: 2026 | B9: 8 | C9: 2026-08 | D9: 1 | E9: 37602 | F9: 0
A10: 2026 | B10: 9 | C10: 2026-09 | D10: 0 | E10: 0 | F10: 0
A11: 2026 | B11: 10 | C11: 2026-10 | D11: 0 | E11: 0 | F11: 0
A12: 2026 | B12: 11 | C12: 2026-11 | D12: 0 | E12: 0 | F12: 0
A13: 2026 | B13: 12 | C13: 2026-12 | D13: 0 | E13: 0 | F13: 0
... A301: 2050 | B301: 12 | C301: 2050-12 | D301: 1 | E301: 92033.116 | F301: 0

Sheet stats_annees
A1: year | B1: renovations_started | C1: renovations_instant | D1: budget_acompte | E1: budget_solde | F1: budget_instant | G1: budget_total_paye | H1: gain_year | I1: gain_cumulatif | J1: gain (%) | K1: Renov moyennes
A2: 2026 | B2: 6 | C2: 1 | D2: 507937.12 | E2: 1035007.8 | F2: 445300 | G2: 1988245 | H2: 338.27048 | I2: 338.27048 | J2: =(0.2+0.8*I2/20843.47)*100 -> 21.298327 | K2: 4.36
A3: 2027 | B3: 6 | C3: 0 | D3: 531905.12 | E3: 1418652.5 | F3: 0 | G3: 1950557.6 | H3: 288.50598 | I3: 626.77646 | J3: =(0.2+0.8*I3/20843.47)*100 -> 22.405651 | K3: 4.36
A4: 2028 | B4: 1 | C4: 0 | D4: 279375.96 | E4: 1705708.6 | F4: 0 | G4: 1985084.6 | H4: 542.90812 | I4: 1169.6846 | J4: =(0.2+0.8*I4/20843.47)*100 -> 24.489404 | K4: 4.36
A5: 2029 | B5: 3 | C5: 0 | D5: 446227.94 | E5: 1514449.5 | F5: 0 | G5: 1960677.4 | H5: 241.15223 | I5: 1410.8368 | J5: =(0.2+0.8*I5/20843.47)*100 -> 25.414979 | K5: 4.36
A6: 2030 | B6: 5 | C6: 0 | D6: 490405.68 | E6: 1442385.5 | F6: 0 | G6: 1932791.2 | H6: 367.75402 | I6: 1778.5908 | J6: =(0.2+0.8*I6/20843.47)*100 -> 26.826467 | K6: 4.36
A7: 2031 | B7: 3 | C7: 0 | D7: 63139.342 | E7: 1924758.9 | F7: 0 | G7: 1987898.3 | H7: 528.81853 | I7: 2307.4094 | J7: =(0.2+0.8*I7/20843.47)*100 -> 28.856143 | K7: 4.36
A8: 2032 | B8: 6 | C8: 1 | D8: 603757.4 | E8: 1312651.4 | F8: 79350 | G8: 1995758.8 | H8: 324.53122 | I8: 2631.9406 | J8: =(0.2+0.8*I8/20843.47)*100 -> 30.101737 | K8: 4.36
A9: 2033 | B9: 3 | C9: 0 | D9: 504901.88 | E9: 1491919.9 | F9: 0 | G9: 1996821.8 | H9: 324.00357 | I9: 2955.9442 | J9: =(0.2+0.8*I9/20843.47)*100 -> 31.345305 | K9: 4.36
A10: 2034 | B10: 1 | C10: 0 | D10: 25943.334 | E10: 1968840.9 | F10: 0 | G10: 1994784.2 | H10: 427.9298 | I10: 3383.874 | J10: =(0.2+0.8*I10/20843.47)*100 -> 32.987757 | K10: 4.36
A11: 2035 | B11: 4 | C11: 1 | D11: 684774.41 | E11: 1299388.1 | F11: 13250 | G11: 1997412.6 | H11: 113.50979 | I11: 3497.3837 | J11: =(0.2+0.8*I11/20843.47)*100 -> 33.423422 | K11: 4.36
A12: 2036 | B12: 5 | C12: 0 | D12: 316063.64 | E12: 1675129.5 | F12: 0 | G12: 1991193.2 | H12: 421.69028 | I12: 3919.074 | J12: =(0.2+0.8*I12/20843.47)*100 -> 35.041925 | K12: 4.36
A13: 2037 | B13: 4 | C13: 0 | D13: 322947.01 | E13: 1649745.8 | F13: 0 | G13: 1972692.8 | H13: 323.98101 | I13: 4243.055 | J13: =(0.2+0.8*I13/20843.47)*100 -> 36.285407 | K13: 4.36
... A26: 2050 | B26: 5 | C26: 0 | D26: 294600.2 | E26: 1608246.3 | F26: 0 | G26: 1902846.5 | H26: 628.38425 | I26: 9421.0625 | J26: =(0.2+0.8*I26/20843.47)*100 -> 56.159286 | K26: 4.36

Sheet disponibilite_detail
A1: period | B1: year | C1: month | D1: category | E1: nb_buildings_total | F1: nb_buildings_active | G1: limit_20pct | H1: taux_occupation | I1: respect_limit | J1: is_exempt
A2: 2026-01 | B2: 2026 | C2: 1 | D2: Sports | E2: 15 | F2: 1 | G2: 3 | H2: 0.066666667 | I2: ✓
A3: 2026-01 | B3: 2026 | C3: 1 | D3: Enseignement | E3: 26 | F3: 1 | G3: 5.2 | H3: 0.038461538 | I3: ✓ | J3: Exempté
A4: 2026-01 | B4: 2026 | C4: 1 | D4: Administration | E4: 5 | F4: 0 | G4: 1 | H4: 0 | I4: ✓
A5: 2026-02 | B5: 2026 | C5: 2 | D5: Sports | E5: 15 | F5: 0 | G5: 3 | H5: 0 | I5: ✓
A6: 2026-02 | B6: 2026 | C6: 2 | D6: Enseignement | E6: 26 | F6: 1 | G6: 5.2 | H6: 0.038461538 | I6: ✓
A7: 2026-02 | B7: 2026 | C7: 2 | D7: Administration | E7: 5 | F7: 0 | G7: 1 | H7: 0 | I7: ✓
A8: 2026-03 | B8: 2026 | C8: 3 | D8: Sports | E8: 15 | F8: 0 | G8: 3 | H8: 0 | I8: ✓
A9: 2026-03 | B9: 2026 | C9: 3 | D9: Enseignement | E9: 26 | F9: 1 | G9: 5.2 | H9: 0.038461538 | I9: ✓
A10: 2026-03 | B10: 2026 | C10: 3 | D10: Administration | E10: 5 | F10: 0 | G10: 1 | H10: 0 | I10: ✓
A11: 2026-04 | B11: 2026 | C11: 4 | D11: Sports | E11: 15 | F11: 0 | G11: 3 | H11: 0 | I11: ✓
A12: 2026-04 | B12: 2026 | C12: 4 | D12: Enseignement | E12: 26 | F12: 1 | G12: 5.2 | H12: 0.038461538 | I12: ✓
A13: 2026-04 | B13: 2026 | C13: 4 | D13: Administration | E13: 5 | F13: 0 | G13: 1 | H13: 0 | I13: ✓
A14: 2026-05 | B14: 2026 | C14: 5 | D14: Sports | E14: 15 | F14: 0 | G14: 3 | H14: 0 | I14: ✓
A15: 2026-05 | B15: 2026 | C15: 5 | D15: Enseignement | E15: 26 | F15: 1 | G15: 5.2 | H15: 0.038461538 | I15: ✓
... A20: 2026-07 | B20: 2026 | C20: 7 | D20: Sports | E20: 15 | F20: 0 | G20: 3 | H20: 0 | I20: ✓
A21: 2026-07 | B21: 2026 | C21: 7 | D21: Enseignement | E21: 26 | F21: 1 | G21: 5.2 | H21: 0.038461538 | I21: ✓ | J21: Exempté
A22: 2026-07 | B22: 2026 | C22: 7 | D22: Administration | E22: 5 | F22: 0 | G22: 1 | H22: 0 | I22: ✓
A23: 2026-08 | B23: 2026 | C23: 8 | D23: Sports | E23: 15 | F23: 0 | G23: 3 | H23: 0 | I23: ✓
A24: 2026-08 | B24: 2026 | C24: 8 | D24: Enseignement | E24: 26 | F24: 1 | G24: 5.2 | H24: 0.038461538 | I24: ✓ | J24: Exempté
A25: 2026-08 | B25: 2026 | C25: 8 | D25: Administration | E25: 5 | F25: 0 | G25: 1 | H25: 0 | I25: ✓
A26: 2026-09 | B26: 2026 | C26: 9 | D26: Sports | E26: 15 | F26: 0 | G26: 3 | H26: 0 | I26: ✓
A27: 2026-09 | B27: 2026 | C27: 9 | D27: Enseignement | E27: 26 | F27: 1 | G27: 5.2 | H27: 0.038461538 | I27: ✓
A28: 2026-09 | B28: 2026 | C28: 9 | D28: Administration | E28: 5 | F28: 0 | G28: 1 | H28: 0 | I28: ✓
A29: 2026-10 | B29: 2026 | C29: 10 | D29: Sports | E29: 15 | F29: 0 | G29: 3 | H29: 0 | I29: ✓
A30: 2026-10 | B30: 2026 | C30: 10 | D30: Enseignement | E30: 26 | F30: 1 | G30: 5.2 | H30: 0.038461538 | I30: ✓
A31: 2026-10 | B31: 2026 | C31: 10 | D31: Administration | E31: 5 | F31: 0 | G31: 1 | H31: 0 | I31: ✓
A32: 2026-11 | B32: 2026 | C32: 11 | D32: Sports | E32: 15 | F32: 0 | G32: 3 | H32: 0 | I32: ✓
A33: 2026-11 | B33: 2026 | C33: 11 | D33: Enseignement | E33: 26 | F33: 1 | G33: 5.2 | H33: 0.038461538 | I33: ✓
A34: 2026-11 | B34: 2026 | C34: 11 | D34: Administration | E34: 5 | F34: 0 | G34: 1 | H34: 0 | I34: ✓
A35: 2026-12 | B35: 2026 | C35: 12 | D35: Sports | E35: 15 | F35: 0 | G35: 3 | H35: 0 | I35: ✓
A36: 2026-12 | B36: 2026 | C36: 12 | D36: Enseignement | E36: 26 | F36: 1 | G36: 5.2 | H36: 0.038461538 | I36: ✓
... A38: 2027-01 | B38: 2027 | C38: 1 | D38: Sports | E38: 15 | F38: 0 | G38: 3 | H38: 0 | I38: ✓
A39: 2027-01 | B39: 2027 | C39: 1 | D39: Enseignement | E39: 26 | F39: 2 | G39: 5.2 | H39: 0.076923077 | I39: ✓ | J39: Exempté
A40: 2027-01 | B40: 2027 | C40: 1 | D40: Administration | E40: 5 | F40: 0 | G40: 1 | H40: 0 | I40: ✓
A41: 2027-02 | B41: 2027 | C41: 2 | D41: Sports | E41: 15 | F41: 0 | G41: 3 | H41: 0 | I41: ✓
A42: 2027-02 | B42: 2027 | C42: 2 | D42: Enseignement | E42: 26 | F42: 1 | G42: 5.2 | H42: 0.038461538 | I42: ✓
A43: 2027-02 | B43: 2027 | C43: 2 | D43: Administration | E43: 5 | F43: 0 | G43: 1 | H43: 0 | I43: ✓
A44: 2027-03 | B44: 2027 | C44: 3 | D44: Sports | E44: 15 | F44: 0 | G44: 3 | H44: 0 | I44: ✓
A45: 2027-03 | B45: 2027 | C45: 3 | D45: Enseignement | E45: 26 | F45: 1 | G45: 5.2 | H45: 0.038461538 | I45: ✓
...

Sheet disponibilite_pivot
A1: category | B1: 2026-01 | C1: 2026-02 | D1: 2026-03 | E1: 2026-04 | F1: 2026-05 | G1: 2026-06 | H1: 2026-07 | I1: 2026-08 | J1: 2026-09 | K1: 2026-10 | L1: 2026-11 | M1: 2026-12 | N1: 2027-01 | O1: 2027-02 | P1: 2027-03 | Q1: 2027-04 | R1: 2027-05 | S1: 2027-06 | T1: 2027-07 | U1: 2027-08 | V1: 2027-09 | W1: 2027-10 | X1: 2027-11 | Y1: 2027-12 | Z1: 2028-01 | AA1: 2028-02 | AB1: 2028-03 | AC1: 2028-04 | AD1: 2028-05 | AE1: 2028-06 | AF1: 2028-07 | AG1: 2028-08 | AH1: 2028-09 | AI1: 2028-10 | AJ1: 2028-11 | AK1: 2028-12 | AL1: 2029-01 | AM1: 2029-02 | AN1: 2029-03 | AO1: 2029-04 | AP1: 2029-05 | AQ1: 2029-06 | AR1: 2029-07 | AS1: 2029-08 | AT1: 2029-09 | AU1: 2029-10 | AV1: 2029-11 | AW1: 2029-12 | AX1: 2030-01 | AY1: 2030-02 | AZ1: 2030-03 | BA1: 2030-04 | BB1: 2030-05 | BC1: 2030-06 | BD1: 2030-07 | BE1: 2030-08 | BF1: 2030-09 | BG1: 2030-10 | BH1: 2030-11 | BI1: 2030-12 | BJ1: 2031-01 | BK1: 2031-02 | BL1: 2031-03 | BM1: 2031-04 | BN1: 2031-05 | BO1: 2031-06 | BP1: 2031-07 | BQ1: 2031-08 | BR1: 2031-09 | BS1: 2031-10 | BT1: 2031-11 | BU1: 2031-12 | BV1: 2032-01 | BW1: 2032-02 | BX1: 2032-03 | BY1: 2032-04 | BZ1: 2032-05 | CA1: 2032-06 | CB1: 2032-07 | CC1: 2032-08 | CD1: 2032-09 | CE1: 2032-10 | CF1: 2032-11 | CG1: 2032-12 | CH1: 2033-01 | CI1: 2033-02 | CJ1: 2033-03 | CK1: 2033-04 | CL1: 2033-05 | CM1: 2033-06 | CN1: 2033-07 | CO1: 2033-08 | CP1: 2033-09 | CQ1: 2033-10 | CR1: 2033-11 | CS1: 2033-12 | CT1: 2034-01 | CU1: 2034-02 | CV1: 2034-03 | CW1: 2034-04 | CX1: 2034-05 | CY1: 2034-06 | CZ1: 2034-07 | DA1: 2034-08 | DB1: 2034-09 | DC1: 2034-10 | DD1: 2034-11 | DE1: 2034-12 | DF1: 2035-01 | DG1: 2035-02 | DH1: 2035-03 | DI1: 2035-04 | DJ1: 2035-05 | DK1: 2035-06 | DL1: 2035-07 | DM1: 2035-08 | DN1: 2035-09 | DO1: 2035-10 | DP1: 2035-11 | DQ1: 2035-12 | DR1: 2036-01 | DS1: 2036-02 | DT1: 2036-03 | DU1: 2036-04 | DV1: 2036-05 | DW1: 2036-06 | DX1: 2036-07 | DY1: 2036-08 | DZ1: 2036-09 | EA1: 2036-10 | EB1: 2036-11 | EC1: 2036-12 | ED1: 2037-01 | EE1: 2037-02 | EF1: 2037-03 | EG1: 2037-04 | EH1: 2037-05 | EI1: 2037-06 | EJ1: 2037-07 | EK1: 2037-08 | EL1: 2037-09 | EM1: 2037-10 | EN1: 2037-11 | EO1: 2037-12 | EP1: 2038-01 | EQ1: 2038-02 | ER1: 2038-03 | ES1: 2038-04 | ET1: 2038-05 | EU1: 2038-06 | EV1: 2038-07 | EW1: 2038-08 | EX1: 2038-09 | EY1: 2038-10 | EZ1: 2038-11 | FA1: 2038-12 | FB1: 2039-01 | FC1: 2039-02 | FD1: 2039-03 | FE1: 2039-04 | FF1: 2039-05 | FG1: 2039-06 | FH1: 2039-07 | FI1: 2039-08 | FJ1: 2039-09 | FK1: 2039-10 | FL1: 2039-11 | FM1: 2039-12 | FN1: 2040-01 | FO1: 2040-02 | FP1: 2040-03 | FQ1: 2040-04 | FR1: 2040-05 | FS1: 2040-06 | FT1: 2040-07 | FU1: 2040-08 | FV1: 2040-09 | FW1: 2040-10 | FX1: 2040-11 | FY1: 2040-12 | FZ1: 2041-01 | GA1: 2041-02 | GB1: 2041-03 | GC1: 2041-04 | GD1: 2041-05 | GE1: 2041-06 | GF1: 2041-07 | GG1: 2041-08 | GH1: 2041-09 | GI1: 2041-10 | GJ1: 2041-11 | GK1: 2041-12 | GL1: 2042-01 | GM1: 2042-02 | GN1: 2042-03 | GO1: 2042-04 | GP1: 2042-05 | GQ1: 2042-06 | GR1: 2042-07 | GS1: 2042-08 | GT1: 2042-09 | GU1: 2042-10 | GV1: 2042-11 | GW1: 2042-12 | GX1: 2043-01 | GY1: 2043-02 | GZ1: 2043-03 | HA1: 2043-04 | HB1: 2043-05 | HC1: 2043-06 | HD1: 2043-07 | HE1: 2043-08 | HF1: 2043-09 | HG1: 2043-10 | HH1: 2043-11 | HI1: 2043-12 | HJ1: 2044-01 | HK1: 2044-02 | HL1: 2044-03 | HM1: 2044-04 | HN1: 2044-05 | HO1: 2044-06 | HP1: 2044-07 | HQ1: 2044-08 | HR1: 2044-09 | HS1: 2044-10 | HT1: 2044-11 | HU1: 2044-12 | HV1: 2045-01 | HW1: 2045-02 | HX1: 2045-03 | HY1: 2045-04 | HZ1: 2045-05 | IA1: 2045-06 | IB1: 2045-07 | IC1: 2045-08 | ID1: 2045-09 | IE1: 2045-10 | IF1: 2045-11 | IG1: 2045-12 | IH1: 2046-01 | II1: 2046-02 | IJ1: 2046-03 | IK1: 2046-04 | IL1: 2046-05 | IM1: 2046-06 | IN1: 2046-07 | IO1: 2046-08 | IP1: 2046-09 | IQ1: 2046-10 | IR1: 2046-11 | IS1: 2046-12 | IT1: 2047-01 | IU1: 2047-02 | IV1: 2047-03 | IW1: 2047-04 | IX1: 2047-05 | IY1: 2047-06 | IZ1: 2047-07 | JA1: 2047-08 | JB1: 2047-09 | JC1: 2047-10 | JD1: 2047-11 | JE1: 2047-12 | JF1: 2048-01 | JG1: 2048-02 | JH1: 2048-03 | JI1: 2048-04 | JJ1: 2048-05 | JK1: 2048-06 | JL1: 2048-07 | JM1: 2048-08 | JN1: 2048-09 | JO1: 2048-10 | JP1: 2048-11 | JQ1: 2048-12 | JR1: 2049-01 | JS1: 2049-02 | JT1: 2049-03 | JU1: 2049-04 | JV1: 2049-05 | JW1: 2049-06 | JX1: 2049-07 | JY1: 2049-08 | JZ1: 2049-09 | KA1: 2049-10 | KB1: 2049-11 | KC1: 2049-12 | KD1: 2050-01 | KE1: 2050-02 | KF1: 2050-03 | KG1: 2050-04 | KH1: 2050-05 | KI1: 2050-06 | KJ1: 2050-07 | KK1: 2050-08 | KL1: 2050-09 | KM1: 2050-10 | KN1: 2050-11 | KO1: 2050-12
A2: Administration | B2: 0 | C2: 0 | D2: 0 | E2: 0 | F2: 0 | G2: 0 | H2: 0 | I2: 0 | J2: 0 | K2: 0 | L2: 0 | M2: 0 | N2: 0 | O2: 0 | P2: 0 | Q2: 0 | R2: 0 | S2: 0 | T2: 0 | U2: 0 | V2: 0 | W2: 0 | X2: 0 | Y2: 0 | Z2: 0 | AA2: 0 | AB2: 0 | AC2: 0 | AD2: 0 | AE2: 0 | AF2: 0 | AG2: 0 | AH2: 0 | AI2: 0 | AJ2: 0 | AK2: 0 | AL2: 0 | AM2: 0 | AN2: 0 | AO2: 0 | AP2: 0 | AQ2: 0 | AR2: 0 | AS2: 0 | AT2: 0 | AU2: 0 | AV2: 0 | AW2: 0 | AX2: 0 | AY2: 0 | AZ2: 0 | BA2: 0 | BB2: 0 | BC2: 0 | BD2: 0 | BE2: 0 | BF2: 0 | BG2: 0 | BH2: 0 | BI2: 1 | BJ2: 0 | BK2: 0 | BL2: 0 | BM2: 0 | BN2: 0 | BO2: 0 | BP2: 0 | BQ2: 0 | BR2: 0 | BS2: 0 | BT2: 0 | BU2: 0 | BV2: 0 | BW2: 0 | BX2: 0 | BY2: 0 | BZ2: 0 | CA2: 0 | CB2: 0 | CC2: 0 | CD2: 0 | CE2: 0 | CF2: 0 | CG2: 0 | CH2: 0 | CI2: 0 | CJ2: 0 | CK2: 0 | CL2: 0 | CM2: 0 | CN2: 0 | CO2: 0 | CP2: 0 | CQ2: 0 | CR2: 0 | CS2: 0 | CT2: 0 | CU2: 0 | CV2: 0 | CW2: 0 | CX2: 0 | CY2: 0 | CZ2: 0 | DA2: 0 | DB2: 0 | DC2: 0 | DD2: 0 | DE2: 0 | DF2: 0 | DG2: 0 | DH2: 0 | DI2: 0 | DJ2: 0 | DK2: 0 | DL2: 0 | DM2: 0 | DN2: 0 | DO2: 0 | DP2: 0 | DQ2: 0 | DR2: 0 | DS2: 0 | DT2: 0 | DU2: 0 | DV2: 0 | DW2: 0 | DX2: 0 | DY2: 0 | DZ2: 0 | EA2: 0 | EB2: 0 | EC2: 1 | ED2: 1 | EE2: 0 | EF2: 0 | EG2: 0 | EH2: 0 | EI2: 0 | EJ2: 0 | EK2: 0 | EL2: 0 | EM2: 0 | EN2: 0 | EO2: 0 | EP2: 0 | EQ2: 0 | ER2: 0 | ES2: 0 | ET2: 0 | EU2: 0 | EV2: 0 | EW2: 0 | EX2: 0 | EY2: 0 | EZ2: 0 | FA2: 0 | FB2: 0 | FC2: 0 | FD2: 0 | FE2: 0 | FF2: 0 | FG2: 0 | FH2: 0 | FI2: 0 | FJ2: 0 | FK2: 0 | FL2: 0 | FM2: 0 | FN2: 0 | FO2: 1 | FP2: 0 | FQ2: 0 | FR2: 0 | FS2: 0 | FT2: 0 | FU2: 1 | FV2: 1 | FW2: 1 | FX2: 1 | FY2: 1 | FZ2: 1 | GA2: 1 | GB2: 1 | GC2: 1 | GD2: 1 | GE2: 1 | GF2: 1 | GG2: 1 | GH2: 1 | GI2: 1 | GJ2: 1 | GK2: 1 | GL2: 1 | GM2: 0 | GN2: 1 | GO2: 1 | GP2: 0 | GQ2: 0 | GR2: 0 | GS2: 0 | GT2: 0 | GU2: 0 | GV2: 0 | GW2: 0 | GX2: 0 | GY2: 0 | GZ2: 0 | HA2: 0 | HB2: 0 | HC2: 0 | HD2: 0 | HE2: 0 | HF2: 0 | HG2: 0 | HH2: 0 | HI2: 0 | HJ2: 0 | HK2: 0 | HL2: 0 | HM2: 0 | HN2: 0 | HO2: 0 | HP2: 0 | HQ2: 0 | HR2: 0 | HS2: 0 | HT2: 0 | HU2: 1 | HV2: 1 | HW2: 0 | HX2: 0 | HY2: 0 | HZ2: 0 | IA2: 0 | IB2: 0 | IC2: 0 | ID2: 0 | IE2: 0 | IF2: 0 | IG2: 0 | IH2: 0 | II2: 0 | IJ2: 0 | IK2: 0 | IL2: 0 | IM2: 0 | IN2: 0 | IO2: 0 | IP2: 0 | IQ2: 0 | IR2: 0 | IS2: 0 | IT2: 0 | IU2: 0 | IV2: 1 | IW2: 1 | IX2: 0 | IY2: 0 | IZ2: 0 | JA2: 0 | JB2: 0 | JC2: 0 | JD2: 0 | JE2: 0 | JF2: 0 | JG2: 0 | JH2: 0 | JI2: 0 | JJ2: 0 | JK2: 0 | JL2: 0 | JM2: 0 | JN2: 0 | JO2: 0 | JP2: 0 | JQ2: 0 | JR2: 0 | JS2: 0 | JT2: 0 | JU2: 0 | JV2: 0 | JW2: 0 | JX2: 0 | JY2: 0 | JZ2: 0 | KA2: 0 | KB2: 0 | KC2: 0 | KD2: 0 | KE2: 0 | KF2: 0 | KG2: 0 | KH2: 0 | KI2: 0 | KJ2: 0 | KK2: 0 | KL2: 0 | KM2: 0 | KN2: 0 | KO2: 0
A3: Enseignement | B3: 1 | C3: 1 | D3: 1 | E3: 1 | F3: 1 | G3: 0 | H3: 1 | I3: 1 | J3: 1 | K3: 1 | L3: 1 | M3: 1 | N3: 2 | O3: 1 | P3: 1 | Q3: 1 | R3: 1 | S3: 1 | T3: 2 | U3: 2 | V3: 2 | W3: 2 | X3: 2 | Y3: 2 | Z3: 2 | AA3: 1 | AB3: 0 | AC3: 0 | AD3: 0 | AE3: 0 | AF3: 0 | AG3: 0 | AH3: 0 | AI3: 0 | AJ3: 1 | AK3: 1 | AL3: 1 | AM3: 1 | AN3: 1 | AO3: 1 | AP3: 0 | AQ3: 0 | AR3: 0 | AS3: 0 | AT3: 0 | AU3: 1 | AV3: 1 | AW3: 0 | AX3: 0 | AY3: 0 | AZ3: 0 | BA3: 0 | BB3: 0 | BC3: 0 | BD3: 0 | BE3: 0 | BF3: 0 | BG3: 0 | BH3: 0 | BI3: 0 | BJ3: 0 | BK3: 0 | BL3: 0 | BM3: 0 | BN3: 0 | BO3: 0 | BP3: 0 | BQ3: 0 | BR3: 0 | BS3: 0 | BT3: 0 | BU3: 0 | BV3: 0 | BW3: 0 | BX3: 1 | BY3: 1 | BZ3: 0 | CA3: 1 | CB3: 1 | CC3: 1 | CD3: 1 | CE3: 1 | CF3: 1 | CG3: 2 | CH3: 1 | CI3: 1 | CJ3: 1 | CK3: 1 | CL3: 1 | CM3: 1 | CN3: 1 | CO3: 1 | CP3: 1 | CQ3: 1 | CR3: 1 | CS3: 1 | CT3: 1 | CU3: 1 | CV3: 1 | CW3: 0 | CX3: 0 | CY3: 0 | CZ3: 0 | DA3: 0 | DB3: 0 | DC3: 0 | DD3: 0 | DE3: 0 | DF3: 0 | DG3: 0 | DH3: 0 | DI3: 0 | DJ3: 0 | DK3: 0 | DL3: 1 | DM3: 1 | DN3: 1 | DO3: 2 | DP3: 2 | DQ3: 2 | DR3: 1 | DS3: 1 | DT3: 1 | DU3: 1 | DV3: 1 | DW3: 1 | DX3: 1 | DY3: 1 | DZ3: 1 | EA3: 1 | EB3: 1 | EC3: 1 | ED3: 1 | EE3: 1 | EF3: 1 | EG3: 0 | EH3: 0 | EI3: 0 | EJ3: 0 | EK3: 1 | EL3: 1 | EM3: 1 | EN3: 1 | EO3: 1 | EP3: 1 | EQ3: 1 | ER3: 1 | ES3: 1 | ET3: 1 | EU3: 1 | EV3: 1 | EW3: 1 | EX3: 2 | EY3: 4 | EZ3: 4 | FA3: 3 | FB3: 2 | FC3: 2 | FD3: 1 | FE3: 1 | FF3: 1 | FG3: 1 | FH3: 1 | FI3: 1 | FJ3: 0 | FK3: 1 | FL3: 1 | FM3: 1 | FN3: 1 | FO3: 1 | FP3: 1 | FQ3: 1 | FR3: 0 | FS3: 0 | FT3: 0 | FU3: 0 | FV3: 0 | FW3: 0 | FX3: 0 | FY3: 0 | FZ3: 0 | GA3: 2 | GB3: 0 | GC3: 0 | GD3: 0 | GE3: 0 | GF3: 0 | GG3: 1 | GH3: 1 | GI3: 1 | GJ3: 1 | GK3: 1 | GL3: 1 | GM3: 1 | GN3: 1 | GO3: 1 | GP3: 2 | GQ3: 2 | GR3: 2 | GS3: 3 | GT3: 1 | GU3: 1 | GV3: 1 | GW3: 2 | GX3: 2 | GY3: 0 | GZ3: 0 | HA3: 0 | HB3: 0 | HC3: 0 | HD3: 0 | HE3: 0 | HF3: 0 | HG3: 0 | HH3: 0 | HI3: 0 | HJ3: 0 | HK3: 0 | HL3: 0 | HM3: 0 | HN3: 0 | HO3: 0 | HP3: 1 | HQ3: 1 | HR3: 1 | HS3: 2 | HT3: 2 | HU3: 1 | HV3: 1 | HW3: 1 | HX3: 1 | HY3: 1 | HZ3: 1 | IA3: 1 | IB3: 1 | IC3: 1 | ID3: 1 | IE3: 1 | IF3: 1 | IG3: 1 | IH3: 1 | II3: 0 | IJ3: 0 | IK3: 0 | IL3: 1 | IM3: 1 | IN3: 1 | IO3: 1 | IP3: 1 | IQ3: 1 | IR3: 1 | IS3: 1 | IT3: 1 | IU3: 1 | IV3: 1 | IW3: 1 | IX3: 1 | IY3: 1 | IZ3: 0 | JA3: 0 | JB3: 0 | JC3: 0 | JD3: 0 | JE3: 0 | JF3: 0 | JG3: 1 | JH3: 1 | JI3: 0 | JJ3: 0 | JK3: 0 | JL3: 0 | JM3: 0 | JN3: 0 | JO3: 0 | JP3: 1 | JQ3: 1 | JR3: 1 | JS3: 1 | JT3: 2 | JU3: 3 | JV3: 3 | JW3: 3 | JX3: 2 | JY3: 2 | JZ3: 2 | KA3: 1 | KB3: 1 | KC3: 1 | KD3: 1 | KE3: 0 | KF3: 0 | KG3: 0 | KH3: 0 | KI3: 1 | KJ3: 1 | KK3: 1 | KL3: 1 | KM3: 1 | KN3: 1 | KO3: 1
A4: Sports | B4: 1 | C4: 0 | D4: 0 | E4: 0 | F4: 0 | G4: 0 | H4: 0 | I4: 0 | J4: 0 | K4: 0 | L4: 0 | M4: 0 | N4: 0 | O4: 0 | P4: 0 | Q4: 0 | R4: 0 | S4: 0 | T4: 0 | U4: 0 | V4: 1 | W4: 1 | X4: 0 | Y4: 0 | Z4: 0 | AA4: 0 | AB4: 0 | AC4: 0 | AD4: 0 | AE4: 0 | AF4: 0 | AG4: 0 | AH4: 0 | AI4: 0 | AJ4: 0 | AK4: 0 | AL4: 0 | AM4: 0 | AN4: 0 | AO4: 0 | AP4: 0 | AQ4: 0 | AR4: 0 | AS4: 0 | AT4: 0 | AU4: 0 | AV4: 0 | AW4: 0 | AX4: 0 | AY4: 0 | AZ4: 0 | BA4: 0 | BB4: 0 | BC4: 0 | BD4: 0 | BE4: 0 | BF4: 0 | BG4: 0 | BH4: 0 | BI4: 0 | BJ4: 0 | BK4: 0 | BL4: 0 | BM4: 0 | BN4: 0 | BO4: 0 | BP4: 0 | BQ4: 0 | BR4: 0 | BS4: 0 | BT4: 0 | BU4: 0 | BV4: 0 | BW4: 0 | BX4: 0 | BY4: 0 | BZ4: 0 | CA4: 0 | CB4: 1 | CC4: 1 | CD4: 1 | CE4: 0 | CF4: 1 | CG4: 1 | CH4: 0 | CI4: 0 | CJ4: 0 | CK4: 0 | CL4: 0 | CM4: 0 | CN4: 0 | CO4: 0 | CP4: 0 | CQ4: 0 | CR4: 0 | CS4: 0 | CT4: 0 | CU4: 0 | CV4: 0 | CW4: 0 | CX4: 0 | CY4: 0 | CZ4: 0 | DA4: 0 | DB4: 0 | DC4: 0 | DD4: 0 | DE4: 0 | DF4: 0 | DG4: 0 | DH4: 0 | DI4: 0 | DJ4: 0 | DK4: 0 | DL4: 0 | DM4: 0 | DN4: 0 | DO4: 0 | DP4: 0 | DQ4: 0 | DR4: 0 | DS4: 0 | DT4: 0 | DU4: 0 | DV4: 0 | DW4: 1 | DX4: 1 | DY4: 1 | DZ4: 1 | EA4: 1 | EB4: 1 | EC4: 2 | ED4: 1 | EE4: 1 | EF4: 0 | EG4: 0 | EH4: 0 | EI4: 0 | EJ4: 0 | EK4: 0 | EL4: 0 | EM4: 1 | EN4: 1 | EO4: 1 | EP4: 0 | EQ4: 0 | ER4: 0 | ES4: 0 | ET4: 1 | EU4: 0 | EV4: 0 | EW4: 0 | EX4: 0 | EY4: 0 | EZ4: 0 | FA4: 1 | FB4: 0 | FC4: 0 | FD4: 0 | FE4: 0 | FF4: 0 | FG4: 0 | FH4: 0 | FI4: 0 | FJ4: 0 | FK4: 0 | FL4: 0 | FM4: 0 | FN4: 0 | FO4: 0 | FP4: 0 | FQ4: 0 | FR4: 0 | FS4: 0 | FT4: 0 | FU4: 0 | FV4: 0 | FW4: 0 | FX4: 0 | FY4: 0 | FZ4: 0 | GA4: 0 | GB4: 0 | GC4: 0 | GD4: 0 | GE4: 0 | GF4: 0 | GG4: 0 | GH4: 0 | GI4: 0 | GJ4: 0 | GK4: 1 | GL4: 1 | GM4: 2 | GN4: 2 | GO4: 2 | GP4: 0 | GQ4: 0 | GR4: 0 | GS4: 0 | GT4: 0 | GU4: 0 | GV4: 0 | GW4: 0 | GX4: 0 | GY4: 0 | GZ4: 1 | HA4: 1 | HB4: 1 | HC4: 1 | HD4: 1 | HE4: 1 | HF4: 1 | HG4: 1 | HH4: 2 | HI4: 1 | HJ4: 1 | HK4: 1 | HL4: 2 | HM4: 0 | HN4: 0 | HO4: 0 | HP4: 0 | HQ4: 0 | HR4: 0 | HS4: 0 | HT4: 0 | HU4: 0 | HV4: 0 | HW4: 0 | HX4: 0 | HY4: 0 | HZ4: 0 | IA4: 0 | IB4: 0 | IC4: 0 | ID4: 0 | IE4: 0 | IF4: 0 | IG4: 0 | IH4: 0 | II4: 0 | IJ4: 0 | IK4: 0 | IL4: 0 | IM4: 0 | IN4: 0 | IO4: 0 | IP4: 0 | IQ4: 0 | IR4: 0 | IS4: 0 | IT4: 0 | IU4: 0 | IV4: 0 | IW4: 1 | IX4: 1 | IY4: 1 | IZ4: 1 | JA4: 1 | JB4: 1 | JC4: 1 | JD4: 0 | JE4: 0 | JF4: 2 | JG4: 2 | JH4: 3 | JI4: 0 | JJ4: 0 | JK4: 0 | JL4: 0 | JM4: 0 | JN4: 0 | JO4: 0 | JP4: 0 | JQ4: 0 | JR4: 0 | JS4: 0 | JT4: 0 | JU4: 0 | JV4: 0 | JW4: 0 | JX4: 0 | JY4: 0 | JZ4: 0 | KA4: 0 | KB4: 0 | KC4: 0 | KD4: 0 | KE4: 0 | KF4: 0 | KG4: 1 | KH4: 1 | KI4: 1 | KJ4: 1 | KK4: 1 | KL4: 1 | KM4: 1 | KN4: 1 | KO4: 1

Sheet Feuil1
A1: category | B1: Administration | C1: Admin(%) | D1: Enseignement | E1: Enseignement(%) | F1: Sports | G1: Sports (%)
A2: 2026-01 | B2: 0 | C2: =B2*100/5 -> 0 | D2: 1 | E2: =100*Feuil1!D2/26 -> 3.8461538 | F2: 1 | G2: =F2*100/15 -> 6.6666667
A3: 2026-02 | B3: 0 | C3: =B3*100/5 -> 0 | D3: 1 | E3: =100*Feuil1!D3/26 -> 3.8461538 | F3: 0 | G3: =F3*100/15 -> 0
A4: 2026-03 | B4: 0 | C4: =B4*100/5 -> 0 | D4: 1 | E4: =100*Feuil1!D4/26 -> 3.8461538 | F4: 0 | G4: =F4*100/15 -> 0
A5: 2026-04 | B5: 0 | C5: =B5*100/5 -> 0 | D5: 1 | E5: =100*Feuil1!D5/26 -> 3.8461538 | F5: 0 | G5: =F5*100/15 -> 0
A6: 2026-05 | B6: 0 | C6: =B6*100/5 -> 0 | D6: 1 | E6: =100*Feuil1!D6/26 -> 3.8461538 | F6: 0 | G6: =F6*100/15 -> 0
A7: 2026-06 | B7: 0 | C7: =B7*100/5 -> 0 | D7: 0 | E7: =100*Feuil1!D7/26 -> 0 | F7: 0 | G7: =F7*100/15 -> 0
A8: 2026-07 | B8: 0 | C8: =B8*100/5 -> 0 | D8: 1 | E8: =100*Feuil1!D8/26 -> 3.8461538 | F8: 0 | G8: =F8*100/15 -> 0
A9: 2026-08 | B9: 0 | C9: =B9*100/5 -> 0 | D9: 1 | E9: =100*Feuil1!D9/26 -> 3.8461538 | F9: 0 | G9: =F9*100/15 -> 0
A10: 2026-09 | B10: 0 | C10: =B10*100/5 -> 0 | D10: 1 | E10: =100*Feuil1!D10/26 -> 3.8461538 | F10: 0 | G10: =F10*100/15 -> 0
A11: 2026-10 | B11: 0 | C11: =B11*100/5 -> 0 | D11: 1 | E11: =100*Feuil1!D11/26 -> 3.8461538 | F11: 0 | G11: =F11*100/15 -> 0
A12: 2026-11 | B12: 0 | C12: =B12*100/5 -> 0 | D12: 1 | E12: =100*Feuil1!D12/26 -> 3.8461538 | F12: 0 | G12: =F12*100/15 -> 0
A13: 2026-12 | B13: 0 | C13: =B13*100/5 -> 0 | D13: 1 | E13: =100*Feuil1!D13/26 -> 3.8461538 | F13: 0 | G13: =F13*100/15 -> 0
... A301: 2050-12 | B301: 0 | C301: =B301*100/5 -> 0 | D301: 1 | E301: =100*Feuil1!D301/26 -> 3.8461538 | F301: 1 | G301: =F301*100/15 -> 6.6666667
A16385: category | B16385: Administration | D16385: Enseignement | F16385: Sports
A16386: 2026-01 | B16386: 0 | D16386: 1 | F16386: 1
A16387: 2026-02 | B16387: 0 | D16387: 1 | F16387: 0
A16388: 2026-03 | B16388: 0 | D16388: 1 | F16388: 0
A16389: 2026-04 | B16389: 0 | D16389: 1 | F16389: 0
A16390: 2026-05 | B16390: 0 | D16390: 1 | F16390: 0
A16391: 2026-06 | B16391: 0 | D16391: 0 | F16391: 0
A16392: 2026-07 | B16392: 0 | D16392: 1 | F16392: 0
A16393: 2026-08 | B16393: 0 | D16393: 1 | F16393: 0
A16394: 2026-09 | B16394: 0 | D16394: 1 | F16394: 0
A16395: 2026-10 | B16395: 0 | D16395: 1 | F16395: 0
A16396: 2026-11 | B16396: 0 | D16396: 1 | F16396: 0
A16397: 2026-12 | B16397: 0 | D16397: 1 | F16397: 0
... A16685: 2050-12 | B16685: 0 | D16685: 1 | F16685: 1
A32769: category | B32769: Administration | D32769: Enseignement | F32769: Sports
A32770: 2026-01 | B32770: 0 | D32770: 1 | F32770: 1
A32771: 2026-02 | B32771: 0 | D32771: 1 | F32771: 0
A32772: 2026-03 | B32772: 0 | D32772: 1 | F32772: 0
A32773: 2026-04 | B32773: 0 | D32773: 1 | F32773: 0
A32774: 2026-05 | B32774: 0 | D32774: 1 | F32774: 0
A32775: 2026-06 | B32775: 0 | D32775: 0 | F32775: 0
A32776: 2026-07 | B32776: 0 | D32776: 1 | F32776: 0
A32777: 2026-08 | B32777: 0 | D32777: 1 | F32777: 0
A32778: 2026-09 | B32778: 0 | D32778: 1 | F32778: 0
A32779: 2026-10 | B32779: 0 | D32779: 1 | F32779: 0
A32780: 2026-11 | B32780: 0 | D32780: 1 | F32780: 0
...
